Workbook
Name _12Excel_BuiltIn_Print_Area_8_6_1: #N/A
Name _2_: #REF!
Name _4Excel_BuiltIn_Print_Area_4_6_1: #N/A
Name _4Excel_BuiltIn_Print_Area_7_6_1: #REF!
Name _4TEN: #REF!
Name _8Excel_BuiltIn_Print_Area_7_6_1: #N/A
Name _Act2: #REF!
Name _DIS1: #REF!
Name _DIS10: #REF!
Name _DIS2: #REF!
Name _DIS3: #REF!
Name _DIS4: #REF!
Name _DIS5: #REF!
Name _DIS6: #REF!
Name _DIS7: #REF!
Name _DIS8: #REF!
Name _DIS9: #REF!
Name _PRO1: #REF!
Name _PRO10: #REF!
Name _PRO2: #REF!
Name _PRO3: #REF!
Name _PRO4: #REF!
Name _PRO5: #REF!
Name _PRO6: #REF!
Name _PRO7: #REF!
Name _PRO8: #REF!
Name _PRO9: #REF!
Name _Sch2: #REF!
Name _Sch3: #REF!
Name _SPV1: "BLV Grundstücksverwaltung GmbH"
Name _SPV2: "PropCo1"
Name _SPV3: "PropCo2"
Name _SPV4: "PropCo3"
Name _SPV5: "PropCo4"
Name _SPV6: "PropCo5"
Name _SPV7: "PropCo6"
Name _YS2: {"'KABA MALZEME'!$B$5:$G$101","'KABA MALZEME'!$B$5:$G$101"}
Name _YS2: {"'KABA MALZEME'!$B$5:$G$101","'KABA MALZEME'!$B$5:$G$101"}
Name _Курс2: #REF!
Name _Курс2_1: #REF!
Name _Курс2_10: #REF!
Name _Курс2_10_12: #REF!
Name _Курс2_10_18: #REF!
Name _Курс2_10_19: #REF!
Name _Курс2_11: #REF!
Name _Курс2_11_12: #REF!
Name _Курс2_11_18: #REF!
Name _Курс2_11_19: #REF!
Name _Курс2_12: #REF!
Name _Курс2_12_12: #REF!
Name _Курс2_12_18: #REF!
Name _Курс2_12_19: #REF!
Name _Курс2_13: #REF!
Name _Курс2_13_12: #REF!
Name _Курс2_13_18: #REF!
Name _Курс2_13_19: #REF!
Name _Курс2_14: #REF!
Name _Курс2_15: #REF!
Name _Курс2_15_12: #REF!
Name _Курс2_15_18: #REF!

Sheet ЕЖЕДНЕВНЫЙ ОТЧЕТ
C2: № | D2: Табельный номер | F2: Должность в структуре | G2: Должность в ОТиЗ | H2: Ф.И.О | I2: Контроль | J2: Компания | K2: Примечания
C3: Ежедневный учет выхода на работу ИТР инженерной службы
C4: Ежедневный учет выхода на работу ИТР инженерной службы ЭОМ и СС
B5: 1 | C5: 1 | D5: 103991 | E5: ЭОМ и СС | F5: Руководитель проекта по ЭОМ и СС | G5: Руководитель проекта по электрическим системам | H5: Юнал Мехмет Бурак | I5: Отпросились | J5: Пальмира Групп | M5: Руководители группы по электро-механическим работам | N5: Э
B6: 1 | C6: 2 | D6: 104006 | E6: ЭОМ и СС | F6: Зам. Руководителя проекта по ЭОМ и СС | G6: Заместитель руководителя проекта по электрическим системам | H6: Агафонов Сергей Анатольевич | J6: Пальмира Групп | M6: Инженер по электро-механическим работам | N6: Э
B7: 1 | C7: 3 | D7: 107297 | E7: ЭОМ и СС | F7: Зам. Руководителя проекта по ЭОМ и СС | H7: Челик Саадеттин | J7: Пальмира Групп | M7: Инженер по электро-механическим работам | N7: Э
B8: 1 | C8: 4 | D8: 106629 | E8: ЭОМ и СС | F8: Руководитель тех.офиса по ЭОМ и СС | G8: Руководитель технического офиса | H8: Ишджен Хюсен Тунджер | J8: Пальмира Групп | M8: Технический офис по электро-механическим работам | N8: Э
B9: 1 | C9: 5 | D9: 104043 | E9: ЭОМ и СС | F9: Руководитель тех.офиса по ЭОМ и СС | G9: Руководитель технического офиса | H9: Текин Гюрбюз | J9: Пальмира Групп | M9: Технический офис по электро-механическим работам | N9: Э
B10: 1 | C10: 6 | D10: 103926 | E10: ЭОМ и СС | F10: Инженер тех. офиса по ЭОМ и СС | G10: Инженер-электрик | H10: Джошкун Уфук | J10: Пальмира Групп | M10: Технический офис по электро-механическим работам | N10: Э
B11: 1 | C11: 7 | D11: 104005 | E11: ЭОМ и СС | F11: Начальник ПТО по ЭОМ и СС | G11: Начальник ПТО | H11: Усманова Феруза Таировна | J11: Пальмира Групп | M11: ПТО по электро-механическим работам | N11: Э
B12: 1 | C12: 8 | D12: 106571 | E12: ЭОМ и СС | F12: Ведущий инженер ПТО по ЭОМ и СС | G12: Ведущий инженер ПТО | H12: Норов Алишер Рустамович | J12: Пальмира Групп | M12: ПТО по электро-механическим работам | N12: Э
B13: 1 | C13: 9 | D13: 106863 | E13: ЭОМ и СС | F13: Ведущий инженер ПТО по ЭОМ и СС | G13: Ведущий инженер ПТО | H13: Вопилин Денис Алексеевич | J13: Пальмира Групп | M13: ПТО по электро-механическим работам | N13: Э
B14: 1 | C14: 10 | D14: 107102 | E14: ЭОМ и СС | F14: Ведущий инженер ПТО по ЭОМ и СС | G14: Ведущий инженер ПТО | H14: Комиссарюк Светлана Ивановна | J14: Пальмира Групп | M14: ПТО по электро-механическим работам | N14: Э
B15: 1 | C15: 11 | D15: 106565 | E15: ЭОМ и СС | F15: Ведущий инженер ЭОМ и СС | G15: Инженер-электрик | H15: Сайбитинов Руслан Раисович | J15: Пальмира Групп | M15: Инженер по электро-механическим работам | N15: Э
B16: 1 | C16: 12 | D16: 106566 | E16: ЭОМ и СС | F16: Ведущий инженер ЭОМ и СС | G16: Инженер технического офиса | H16: Зейналов Самир Рамил Оглы | J16: Пальмира Групп | M16: Технический офис по электро-механическим работам | N16: Э
B17: 1 | C17: 13 | D17: 107298 | E17: ЭОМ и СС | F17: Ведущий инженер ЭОМ и СС | H17: Дилек Селахаттин | J17: Пальмира Групп | M17: Инженер по электро-механическим работам | N17: Э
B18: 1 | C18: 14 | D18: 106312 | E18: ЭОМ и СС | F18: Инженер дизайн-офиса по ЭОМ и СС | G18: Инженер-электрик | H18: Сумер Гул | I18: Работает на А24 | J18: Пальмира Групп | M18: Инженер по электро-механическим работам | N18: Э
B19: 1 | C19: 15 | D19: 106313 | E19: ЭОМ и СС | F19: Инженер дизайн-офиса по ЭОМ и СС | G19: Инженер-электрик | H19: Джомерт Мурат | J19: Пальмира Групп | K19: Турция | M19: Инженер по электро-механическим работам | N19: Э
B20: 1 | C20: 16 | D20: 106750 | E20: ЭОМ и СС | F20: Администратор по ЭОМ и СС | G20: Администратор | H20: Кристев Иван Иванович | J20: Пальмира Групп | M20: Инженер по электро-механическим работам | N20: Э
B21: 1 | C21: 17 | D21: 102191 | E21: ЭОМ и СС | F21: Пом. кладовщика | G21: Подсобный рабочий | H21: Самандаров Дастонбек Рашидович | I21: Работает на А24 | J21: Пальмира Групп | K21: Специалист по пожарной системы | M21: Работник склада | N21: Э
C22: Ежедневный учет выхода на работу ИТР инженерной службы ОВ и ВК
B23: 1 | C23: 18 | D23: 101339 | E23: ОВ и ВК | F23: Пом. Координатора по Механике | G23: Руководитель технического офиса | H23: Йалчынели Бахадыр | I23: Работает на А24 | J23: Пальмира Групп | M23: Инженер по электро-механическим работам | N23: М
B24: 1 | C24: 19 | D24: 104008 | E24: ОВ и ВК | F24: Руководитель проекта по ОВ и ВК | G24: Главный механик | H24: Озекес Емре | J24: Пальмира Групп | M24: Руководители группы по электро-механическим работам | N24: М
B25: 1 | C25: 20 | D25: 104722 | E25: ОВ и ВК | F25: Зам. Руководителя проекта по ОВ и ВК | G25: Инженер по наладке и испытаниям | H25: Рафиев Зиёдулло | J25: Пальмира Групп | M25: Инженер по электро-механическим работам | N25: М
B26: 1 | C26: 21 | D26: 106305 | E26: ОВ и ВК | F26: Начальник тех.офиса по ОВ и ВК | G26: Инженер | H26: Кармилов Мурат | J26: Пальмира Групп | M26: Технический офис по электро-механическим работам | N26: М
B27: 1 | C27: 22 | D27: 107296 | E27: ОВ и ВК | F27: Инженер тех. офиса по ОВ и ВК | G27: Инженер технического офиса | H27: Ниязов Хомид Самадович | J27: Пальмира Групп | M27: Технический офис по электро-механическим работам | N27: М
B28: 1 | C28: 23 | D28: 106724 | E28: ОВ и ВК | F28: Инженер Дизайн-офиса по Ревит ВИС | G28: Инженер (Инженер по механике) | H28: Аяз Эрман | J28: Пальмира Групп | M28: Инженер по электро-механическим работам | N28: М
B29: 1 | C29: 24 | D29: 104778 | E29: ОВ и ВК | F29: Инженер Дизайн-офиса по Ревит ВИС | G29: Инженер (Инженер по механике) | H29: Чобан Эмре | I29: Работает на А24 | J29: Пальмира Групп | M29: Инженер по электро-механическим работам | N29: М
B30: 1 | C30: 25 | D30: 106459 | E30: ОВ и ВК | F30: Инженер ОВ и ВК | G30: Инженер | H30: Алиев Мустафа Юсупович | J30: Пальмира Групп | M30: Инженер по электро-механическим работам | N30: М
B31: 1 | C31: 26 | D31: 106749 | E31: ОВ и ВК | F31: Инженер ОВ и ВК | G31: Инженер | H31: Патапеня Павел Александрович | J31: Пальмира Групп | M31: Инженер по электро-механическим работам | N31: М
B32: 1 | C32: 27 | D32: 104401 | E32: ОВ и ВК | F32: Главный Инженер (ГИП) по ОВ и ВК | G32: Главный инженер | H32: Енин Руслан Николаевич | J32: Пальмира Групп | M32: Инженер по электро-механическим работам | N32: М
B33: 1 | C33: 28 | D33: 102207 | E33: ОВ и ВК | F33: Начальник ПТО по ОВ и ВК | G33: Начальник группы ПТО | H33: Кулигин Игнат Геннадиевич | J33: Пальмира Групп | M33: ПТО по электро-механическим работам | N33: М
B34: 1 | C34: 29 | D34: 107330 | E34: ОВ и ВК | F34: Инженер ПТО по ОВ и ВК | G34: Инженер ПТО | H34: Мередов Керим | J34: Пальмира Групп | M34: ПТО по электро-механическим работам | N34: М
B35: 1 | C35: 30 | D35: 106621 | E35: ОВ и ВК | F35: Пом.Инженера ПТО ОВ и ВК | G35: Подсобный рабочий | H35: Атаниязов Дилшод Камилжан Угли | J35: Пальмира Групп | M35: ПТО по электро-механическим работам | N35: М
B36: 1 | C36: 31 | D36: 106912 | E36: ОВ и ВК | F36: Пом.Инженера ПТО ОВ и ВК | G36: Подсобный рабочий | H36: Хамраев Шахзод Кадамбай Угли | J36: Пальмира Групп | M36: ПТО по электро-механическим работам | N36: М
B37: 1 | C37: 32 | D37: 106404 | E37: ОВ и ВК | F37: Пом. кладовщика | G37: Кладовщик | H37: Муминов Мухаммадшариф Холикулович | J37: Пальмира Групп | K37: Оператор ПК (Кладовка) | M37: Работник склада | N37: М
B38: 1 | C38: 33 | D38: 105214 | E38: ОВ и ВК | F38: Пом. кладовщика | G38: Слесарь-сантехник | H38: Садиков Бекзод Кенжабой Угли | J38: Пальмира Групп | M38: Работник склада | N38: М
B39: 1 | C39: 34 | D39: 106130 | E39: ОВ и ВК | F39: Пом. кладовщика | G39: Слесарь-сантехник | H39: Жалимбетов Суннатилло Усманбой Угли | J39: Пальмира Групп | M39: Работник склада | N39: М
B40: 1 | C40: 35 | D40: 106128 | E40: ОВ и ВК | F40: Пом. кладовщика | G40: Слесарь-сантехник | H40: Каримов Сухроббек Ахмаджон Угли | J40: Пальмира Групп | M40: Работник склада | N40: М
B41: 1 | C41: 36 | D41: 106816 | E41: ОВ и ВК | F41: Пом. кладовщика | G41: Кладовщик | H41: Узун Оглы Хасан Мухамедович | J41: Пальмира Групп | K41: Оператор ПК | M41: Работник склада | N41: М
...

Sheet РАСХОД ЗА МЕСЯЦ
A1: № | B1: Табельный номер | C1: Ф.И.О | D1: Должность | E1: 46054 | AG1: Отработанные часы A27 | AH1: Примечания
E2: 1 | F2: 2 | G2: 3 | H2: 4 | I2: 5 | J2: 6 | K2: 7 | L2: 8 | M2: 9 | N2: 10 | O2: 11 | P2: 12 | Q2: 13 | R2: 14 | S2: 15 | T2: 16 | U2: 17 | V2: 18 | W2: 19 | X2: 20 | Y2: 21 | Z2: 22 | AA2: 23 | AB2: 24 | AC2: 25 | AD2: 26 | AE2: 27 | AF2: 28
A3: Табель учета рабочего времени | AQ3: УФМС
A4: 1 | B4: 105708 | C4: Илёсов Рахмонжон Хасанбой Угли | D4: Бригада 1 класса по ЭОМ и СС (İyi Seviye Usta) | E4: 0 | F4: 0 | G4: 10 | H4: 10 | I4: 10 | J4: 10 | K4: 10 | L4: 8 | M4: 10 | N4: 0 | O4: 10 | AG4: =SUM(E4:AF4) -> 78 | AQ4: Больничный
A5: 2 | B5: 105698 | C5: Тохиров Исмоилжон Исроилжон Угли | D5: Бригада 2 класса по ЭОМ и СС (Orta Seviye Usta) | E5: 8 | F5: 0 | G5: 0 | H5: 10 | I5: 10 | J5: 10 | K5: 0 | L5: 8 | M5: 10 | N5: 10 | O5: 10 | AG5: =SUM(E5:AF5) -> 76 | AQ5: Командировка
A6: 3 | B6: 106549 | C6: Мамуржонов Огабек Садридин Угли | D6: Бригада 2 класса по ЭОМ и СС (Orta Seviye Usta) | E6: 0 | F6: 0 | G6: 10 | H6: 10 | I6: 0 | J6: 0 | K6: 10 | L6: 0 | M6: 10 | N6: 0 | O6: 10 | AG6: =SUM(E6:AF6) -> 50 | AQ6: Отсутствовал без причины
A7: 4 | B7: 106417 | C7: Касимов Асадулло Таваккалович | D7: Бригада 2 класса по ЭОМ и СС (Orta Seviye Usta) | E7: 8 | F7: 10 | G7: 10 | H7: 10 | I7: 10 | J7: 10 | K7: 10 | L7: 0 | M7: 10 | N7: 10 | O7: 10 | AG7: =SUM(E7:AF7) -> 98 | AQ7: Выходной день
A8: 5 | B8: 102112 | C8: Самандаров Дилшод Рашид Угли | D8: Пом. кладовщика | E8: 8 | F8: 10 | G8: 10 | H8: 10 | I8: 10 | J8: 10 | K8: 10 | L8: 8 | M8: 10 | N8: 10 | O8: 10 | AG8: =SUM(E8:AF8) -> 106 | AQ8: Отпуск
A9: 6 | B9: 105265 | C9: Очилдиев Азамжон Нурматович | D9: Пом. кладовщика | E9: 8 | F9: 10 | G9: 10 | H9: 10 | I9: 10 | J9: 10 | K9: 10 | L9: 8 | M9: 10 | N9: 10 | O9: 10 | AG9: =SUM(E9:AF9) -> 106
A10: 7 | B10: 105704 | C10: Гофуржонов Комронбек Журабек Угли | D10: Бригада 1 класса по ЭОМ и СС (İyi Seviye Usta) | E10: 0 | F10: 10 | G10: 0 | H10: 10 | I10: 10 | J10: 10 | K10: 10 | L10: 8 | M10: 10 | N10: 10 | O10: 10 | AG10: =SUM(E10:AF10) -> 88 | AQ10: Отпросились
A11: 8 | B11: 105703 | C11: Муллажонов Зиёдуллох Зафаржон Угли | D11: Бригада 2 класса по ЭОМ и СС (Orta Seviye Usta) | E11: 0 | F11: 10 | G11: 10 | H11: 10 | I11: 10 | J11: 10 | K11: 10 | L11: 8 | M11: 10 | N11: 10 | O11: 10 | AG11: =SUM(E11:AF11) -> 98 | AQ11: Работает на А24
A12: 9 | B12: 105707 | C12: Нишонбоев Мухаммадзиё Рахмонали Угли | D12: Бригада 1 класса по ЭОМ и СС (İyi Seviye Usta) | E12: 0 | F12: 10 | G12: 0 | H12: 10 | I12: 10 | J12: 0 | K12: 10 | L12: 8 | M12: 10 | N12: 10 | O12: 10 | AG12: =SUM(E12:AF12) -> 78 | AQ12: Ожидание Патента ЭОМ и СС
A13: 10 | B13: 105705 | C13: Юлдошбоев Файзулло Музаффаржон Угли | D13: Бригада 1 класса по ЭОМ и СС (İyi Seviye Usta) | E13: 0 | F13: 10 | G13: 0 | H13: 0 | I13: 10 | J13: 10 | K13: 10 | L13: 0 | M13: 10 | N13: 0 | O13: 10 | AG13: =SUM(E13:AF13) -> 60 | AQ13: Проверка Документов ЭОМ и СС
A14: 11 | B14: 105833 | C14: Хужанов Шокир Менгибаевич | D14: Бригада 3 класса по ЭОМ и СС (Alt Seviye Usta) | E14: 0 | F14: 10 | G14: 10 | H14: 10 | I14: 10 | J14: 10 | K14: 10 | L14: 8 | M14: 10 | N14: 10 | O14: 10 | AG14: =SUM(E14:AF14) -> 98 | AQ14: Перевод с другого объекта ЭОМ и СС
A15: 12 | B15: 105858 | C15: Жумаев Исломбек Эшмурод Угли | D15: Бригада 2 класса по ЭОМ и СС (Orta Seviye Usta) | E15: 0 | F15: 10 | G15: 10 | H15: 10 | I15: 10 | J15: 10 | K15: 10 | L15: 8 | M15: 10 | N15: 10 | O15: 10 | AG15: =SUM(E15:AF15) -> 98 | AQ15: Ожидание Патента ОВ и ВК
A16: 13 | B16: 106122 | C16: Ахтамжонов Сажжод Фаррух Угли | D16: Бригада 3 класса по ЭОМ и СС (Alt Seviye Usta) | E16: 0 | F16: 10 | G16: 10 | H16: 10 | I16: 10 | J16: 10 | K16: 0 | L16: 8 | M16: 10 | N16: 10 | O16: 10 | AG16: =SUM(E16:AF16) -> 88 | AQ16: Проверка Документов ОВ и ВК
A17: 14 | B17: 106548 | C17: Абдуллаев Фаррух Эркинович | D17: Бригада 1 класса по ЭОМ и СС (İyi Seviye Usta) | E17: 0 | F17: 10 | G17: 10 | H17: 10 | I17: 10 | J17: 10 | K17: 10 | L17: 8 | M17: 10 | N17: 10 | O17: 10 | AG17: =SUM(E17:AF17) -> 98 | AQ17: Перевод с другого объекта ОВ и ВК
A18: 15 | B18: 104620 | C18: Джунаев Умиджон Абиджонович | D18: Бригада 2 класса по ЭОМ и СС (Orta Seviye Usta) | E18: 0 | F18: 10 | G18: 10 | H18: 10 | I18: 10 | J18: 10 | K18: 10 | L18: 8 | M18: 10 | N18: 10 | O18: 10 | AG18: =SUM(E18:AF18) -> 98
A19: 16 | B19: 101363 | C19: Эрметов Озод Шерипбаевич | D19: Бригада 2 класса по ЭОМ и СС (Orta Seviye Usta) | E19: 0 | F19: 10 | G19: 10 | H19: 10 | I19: 10 | J19: 10 | K19: 0 | L19: 0 | M19: 0 | N19: 0 | O19: 0 | AG19: =SUM(E19:AF19) -> 50
A20: 17 | AG20: =SUM(E20:AF20) -> 0
AG21: =SUM(AG4:AG20) -> 1368
A22: Табель учета рабочего времени ПО МОБИЛИЗАЦИИ
A23: 1 | B23: 105584 | C23: Рейимбердиев Закир Мирза Угли | D23: Бригада 1 класса по ЭОМ и СС (İyi Seviye Usta) | E23: 8 | F23: 10 | G23: 10 | H23: 10 | I23: 10 | J23: 10 | K23: 0 | L23: 0 | M23: 10 | N23: 10 | O23: 10 | AG23: =SUM(E23:AF23) -> 88
A24: 2 | B24: 105600 | C24: Сабиров Огабек Атабек Угли | D24: Пом.в бригаде по ЭОМ и СС (Usta Yrd.) | E24: 8 | F24: 10 | G24: 10 | H24: 10 | I24: 10 | J24: 10 | K24: 10 | L24: 0 | M24: 10 | N24: 10 | O24: 10 | AG24: =SUM(E24:AF24) -> 98
A25: 3 | B25: 102902 | C25: Матякубов Джуманияз Раджапбаевич | D25: Пом.в бригаде по ЭОМ и СС (Usta Yrd.) | E25: 8 | F25: 10 | G25: 10 | H25: 10 | I25: 10 | J25: 10 | K25: 10 | L25: 0 | M25: 10 | N25: 10 | O25: 10 | AG25: =SUM(E25:AF25) -> 98
A26: 4 | B26: 107098 | C26: Юсупов Огабек Кудрат Угли | D26: Пом.в бригаде по ЭОМ и СС (Usta Yrd.) | E26: 8 | F26: 0 | G26: 0 | H26: 0 | I26: 10 | J26: 10 | K26: 10 | L26: 8 | M26: 10 | N26: 10 | O26: 10 | AG26: =SUM(E26:AF26) -> 76
A27: 5 | B27: 107349 | C27: Абдикаримов Хусниддин Валиевич | D27: Пом.в бригаде по ЭОМ и СС (Usta Yrd.) | E27: 8 | F27: 10 | G27: 10 | H27: 10 | I27: 10 | J27: 10 | K27: 10 | L27: 0 | M27: 10 | N27: 10 | O27: 10 | AG27: =SUM(E27:AF27) -> 98
A28: 6 | B28: 106191 | C28: Сапарбаев Рашид Фарход Угли | D28: Пом.в бригаде по ЭОМ и СС (Usta Yrd.) | E28: 0 | F28: 10 | G28: 10 | H28: 10 | I28: 10 | J28: 10 | K28: 10 | L28: 8 | M28: 10 | N28: 0 | O28: 0 | AG28: =SUM(E28:AF28) -> 78
A29: 7 | B29: 106192 | C29: Аминов Сухроб Жуманазар Угли | D29: Пом.в бригаде по ЭОМ и СС (Usta Yrd.) | E29: 0 | F29: 10 | G29: 10 | H29: 10 | I29: 10 | J29: 10 | K29: 10 | L29: 8 | M29: 10 | N29: 10 | O29: 10 | AG29: =SUM(E29:AF29) -> 98
A30: 8 | B30: 101530 | C30: Зарибов Кувончбек Шоназар Угли | D30: Бригада 2 класса по ЭОМ и СС (Orta Seviye Usta) | E30: 0 | F30: 0 | G30: 0 | H30: 0 | I30: 0 | J30: 10 | K30: 10 | L30: 8 | M30: 10 | N30: 10 | O30: 10 | AG30: =SUM(E30:AF30) -> 58
A31: 9 | B31: 101302 | C31: Махмадов Фарух Амиршоевич | D31: Бригада 2 класса по ЭОМ и СС (Orta Seviye Usta) | E31: 0 | F31: 0 | G31: 0 | H31: 0 | I31: 0 | J31: 10 | K31: 10 | L31: 8 | M31: 10 | N31: 10 | O31: 10 | AG31: =SUM(E31:AF31) -> 58
A32: 10 | B32: 107723 | C32: Садуллаев Дониёр Икрам Угли | D32: Бригада 2 класса по ЭОМ и СС (Orta Seviye Usta) | E32: 0 | F32: 0 | G32: 0 | H32: 0 | I32: 0 | J32: 10 | K32: 10 | L32: 8 | M32: 0 | N32: 10 | O32: 0 | AG32: =SUM(E32:AF32) -> 38
A33: 11 | AG33: =SUM(E33:AF33) -> 0
A34: 12 | AG34: =SUM(E34:AF34) -> 0
A35: 13 | AG35: =SUM(E35:AF35) -> 0
A36: 14 | AG36: =SUM(E36:AF36) -> 0
A37: 15 | AG37: =SUM(E37:AF37) -> 0
A38: 16 | AG38: =SUM(E38:AF38) -> 0
A39: 17 | AG39: =SUM(E39:AF39) -> 0
AG40: =SUM(AG23:AG39) -> 788
...

Sheet СКУД (турникет)
A1: ДЕЛАЕТСЯ В ВИДЕ ОТЧЕТА ПО СКУД

Sheet ОВ и ВК
C1: Saha Direkt Çalışan Personel
B2: № | C2: ОВ и ВК Рабочие | D2: Общ. Кол-тво | E2: Отсутствовал без причины | F2: Командировка | G2: УФМС | H2: Больничный | I2: Выходной день | J2: Отпуск | K2: Отпросились | L2: Работает на А24 | M2: Чистое кол-во на площадке
B3: 1 | C3: Вентиляция | D3: =COUNTIFS('ЕЖЕДНЕВНЫЙ ОТЧЕТ'!$L:$L,$B3) -> 66 | E3: =COUNTIFS('ЕЖЕДНЕВНЫЙ ОТЧЕТ'!$L:$L,$B3,'ЕЖЕДНЕВНЫЙ ОТЧЕТ'!$I:$I,E$2) -> 2 | F3: =COUNTIFS('ЕЖЕДНЕВНЫЙ ОТЧЕТ'!$L:$L,$B3,'ЕЖЕДНЕВНЫЙ ОТЧЕТ'!$I:$I,F$2) -> 0 | G3: =COUNTIFS('ЕЖЕДНЕВНЫЙ ОТЧЕТ'!$L:$L,$B3,'ЕЖЕДНЕВНЫЙ ОТЧЕТ'!$I:$I,G$2) -> 0 | H3: =COUNTIFS('ЕЖЕДНЕВНЫЙ ОТЧЕТ'!$L:$L,$B3,'ЕЖЕДНЕВНЫЙ ОТЧЕТ'!$I:$I,H$2) -> 0 | I3: =COUNTIFS('ЕЖЕДНЕВНЫЙ ОТЧЕТ'!$L:$L,$B3,'ЕЖЕДНЕВНЫЙ ОТЧЕТ'!$I:$I,I$2) -> 0 | J3: =COUNTIFS('ЕЖЕДНЕВНЫЙ ОТЧЕТ'!$L:$L,$B3,'ЕЖЕДНЕВНЫЙ ОТЧЕТ'!$I:$I,J$2) -> 1 | K3: =COUNTIFS('ЕЖЕДНЕВНЫЙ ОТЧЕТ'!$L:$L,$B3,'ЕЖЕДНЕВНЫЙ ОТЧЕТ'!$I:$I,K$2) -> 0 | L3: =COUNTIFS('ЕЖЕДНЕВНЫЙ ОТЧЕТ'!$L:$L,$B3,'ЕЖЕДНЕВНЫЙ ОТЧЕТ'!$I:$I,L$2) -> 5 | M3: =D3-SUM(E3:L3) -> 58
B4: 2 | C4: Сантехника | D4: =COUNTIFS('ЕЖЕДНЕВНЫЙ ОТЧЕТ'!$L:$L,$B4) -> 38 | E4: =COUNTIFS('ЕЖЕДНЕВНЫЙ ОТЧЕТ'!$L:$L,$B4,'ЕЖЕДНЕВНЫЙ ОТЧЕТ'!$I:$I,E$2) -> 2 | F4: =COUNTIFS('ЕЖЕДНЕВНЫЙ ОТЧЕТ'!$L:$L,$B4,'ЕЖЕДНЕВНЫЙ ОТЧЕТ'!$I:$I,F$2) -> 0 | G4: =COUNTIFS('ЕЖЕДНЕВНЫЙ ОТЧЕТ'!$L:$L,$B4,'ЕЖЕДНЕВНЫЙ ОТЧЕТ'!$I:$I,G$2) -> 0 | H4: =COUNTIFS('ЕЖЕДНЕВНЫЙ ОТЧЕТ'!$L:$L,$B4,'ЕЖЕДНЕВНЫЙ ОТЧЕТ'!$I:$I,H$2) -> 0 | I4: =COUNTIFS('ЕЖЕДНЕВНЫЙ ОТЧЕТ'!$L:$L,$B4,'ЕЖЕДНЕВНЫЙ ОТЧЕТ'!$I:$I,I$2) -> 0 | J4: =COUNTIFS('ЕЖЕДНЕВНЫЙ ОТЧЕТ'!$L:$L,$B4,'ЕЖЕДНЕВНЫЙ ОТЧЕТ'!$I:$I,J$2) -> 0 | K4: =COUNTIFS('ЕЖЕДНЕВНЫЙ ОТЧЕТ'!$L:$L,$B4,'ЕЖЕДНЕВНЫЙ ОТЧЕТ'!$I:$I,K$2) -> 0 | L4: =COUNTIFS('ЕЖЕДНЕВНЫЙ ОТЧЕТ'!$L:$L,$B4,'ЕЖЕДНЕВНЫЙ ОТЧЕТ'!$I:$I,L$2) -> 0 | M4: =D4-SUM(E4:L4) -> 36
D5: =SUM(D3:D4) -> 104 | E5: =SUM(E3:E4) -> 4 | F5: =SUM(F3:F4) -> 0 | G5: =SUM(G3:G4) -> 0 | H5: =SUM(H3:H4) -> 0 | I5: =SUM(I3:I4) -> 0 | J5: =SUM(J3:J4) -> 1 | K5: =SUM(K3:K4) -> 0 | ... M5: =SUM(M3:M4) -> 94

Sheet Отчет по Строительство
D3: Дата: | E3: 46017 | F3: Объект: капитального строительства «Офисно-деловое здание» по адресу: г. Москва, внутригородское муниципальное образование Кунцево, у д.Захарково, квартал А27»
D14: Электро-Механик ИТР | I14: Э | J14: М
D15: 1 | E15: Руководители группы по электро-механическим работам | H15: =COUNTIFS('ЕЖЕДНЕВНЫЙ ОТЧЕТ'!$M$5:$M$410,'Отчет по Строительство'!E15,'ЕЖЕДНЕВНЫЙ ОТЧЕТ'!$I$5:$I$410,"") -> 1 | I15: =COUNTIFS('ЕЖЕДНЕВНЫЙ ОТЧЕТ'!$M$5:$M$410,'Отчет по Строительство'!E15,'ЕЖЕДНЕВНЫЙ ОТЧЕТ'!$I$5:$I$410,"",'ЕЖЕДНЕВНЫЙ ОТЧЕТ'!$N$5:$N$410,$I$14) -> 0 | J15: =COUNTIFS('ЕЖЕДНЕВНЫЙ ОТЧЕТ'!$M$5:$M$410,'Отчет по Строительство'!E15,'ЕЖЕДНЕВНЫЙ ОТЧЕТ'!$I$5:$I$410,"",'ЕЖЕДНЕВНЫЙ ОТЧЕТ'!$N$5:$N$410,$J$14) -> 1
D16: 2 | E16: Технический офис по электро-механическим работам | H16: =COUNTIFS('ЕЖЕДНЕВНЫЙ ОТЧЕТ'!$M$5:$M$410,'Отчет по Строительство'!E16,'ЕЖЕДНЕВНЫЙ ОТЧЕТ'!$I$5:$I$410,"") -> 6 | I16: =COUNTIFS('ЕЖЕДНЕВНЫЙ ОТЧЕТ'!$M$5:$M$410,'Отчет по Строительство'!E16,'ЕЖЕДНЕВНЫЙ ОТЧЕТ'!$I$5:$I$410,"",'ЕЖЕДНЕВНЫЙ ОТЧЕТ'!$N$5:$N$410,$I$14) -> 4 | J16: =COUNTIFS('ЕЖЕДНЕВНЫЙ ОТЧЕТ'!$M$5:$M$410,'Отчет по Строительство'!E16,'ЕЖЕДНЕВНЫЙ ОТЧЕТ'!$I$5:$I$410,"",'ЕЖЕДНЕВНЫЙ ОТЧЕТ'!$N$5:$N$410,$J$14) -> 2
D17: 3 | E17: Инженер по электро-механическим работам | H17: =COUNTIFS('ЕЖЕДНЕВНЫЙ ОТЧЕТ'!$M$5:$M$410,'Отчет по Строительство'!E17,'ЕЖЕДНЕВНЫЙ ОТЧЕТ'!$I$5:$I$410,"") -> 14 | I17: =COUNTIFS('ЕЖЕДНЕВНЫЙ ОТЧЕТ'!$M$5:$M$410,'Отчет по Строительство'!E17,'ЕЖЕДНЕВНЫЙ ОТЧЕТ'!$I$5:$I$410,"",'ЕЖЕДНЕВНЫЙ ОТЧЕТ'!$N$5:$N$410,$I$14) -> 7 | J17: =COUNTIFS('ЕЖЕДНЕВНЫЙ ОТЧЕТ'!$M$5:$M$410,'Отчет по Строительство'!E17,'ЕЖЕДНЕВНЫЙ ОТЧЕТ'!$I$5:$I$410,"",'ЕЖЕДНЕВНЫЙ ОТЧЕТ'!$N$5:$N$410,$J$14) -> 7
D18: 4 | E18: ПТО по электро-механическим работам | H18: =COUNTIFS('ЕЖЕДНЕВНЫЙ ОТЧЕТ'!$M$5:$M$410,'Отчет по Строительство'!E18,'ЕЖЕДНЕВНЫЙ ОТЧЕТ'!$I$5:$I$410,"") -> 8 | I18: =COUNTIFS('ЕЖЕДНЕВНЫЙ ОТЧЕТ'!$M$5:$M$410,'Отчет по Строительство'!E18,'ЕЖЕДНЕВНЫЙ ОТЧЕТ'!$I$5:$I$410,"",'ЕЖЕДНЕВНЫЙ ОТЧЕТ'!$N$5:$N$410,$I$14) -> 4 | J18: =COUNTIFS('ЕЖЕДНЕВНЫЙ ОТЧЕТ'!$M$5:$M$410,'Отчет по Строительство'!E18,'ЕЖЕДНЕВНЫЙ ОТЧЕТ'!$I$5:$I$410,"",'ЕЖЕДНЕВНЫЙ ОТЧЕТ'!$N$5:$N$410,$J$14) -> 4
D19: 5 | E19: ОТиТБ по электро-механическим работам | H19: =COUNTIFS('ЕЖЕДНЕВНЫЙ ОТЧЕТ'!$M$5:$M$410,'Отчет по Строительство'!E19,'ЕЖЕДНЕВНЫЙ ОТЧЕТ'!$I$5:$I$410,"") -> 1 | I19: =COUNTIFS('ЕЖЕДНЕВНЫЙ ОТЧЕТ'!$M$5:$M$410,'Отчет по Строительство'!E19,'ЕЖЕДНЕВНЫЙ ОТЧЕТ'!$I$5:$I$410,"",'ЕЖЕДНЕВНЫЙ ОТЧЕТ'!$N$5:$N$410,$I$14) -> 0 | J19: =COUNTIFS('ЕЖЕДНЕВНЫЙ ОТЧЕТ'!$M$5:$M$410,'Отчет по Строительство'!E19,'ЕЖЕДНЕВНЫЙ ОТЧЕТ'!$I$5:$I$410,"",'ЕЖЕДНЕВНЫЙ ОТЧЕТ'!$N$5:$N$410,$J$14) -> 1
D20: 6 | E20: Закупки и логистика | H20: =COUNTIFS('ЕЖЕДНЕВНЫЙ ОТЧЕТ'!$M$5:$M$410,'Отчет по Строительство'!E20,'ЕЖЕДНЕВНЫЙ ОТЧЕТ'!$I$5:$I$410,"") -> 1 | I20: =COUNTIFS('ЕЖЕДНЕВНЫЙ ОТЧЕТ'!$M$5:$M$410,'Отчет по Строительство'!E20,'ЕЖЕДНЕВНЫЙ ОТЧЕТ'!$I$5:$I$410,"",'ЕЖЕДНЕВНЫЙ ОТЧЕТ'!$N$5:$N$410,$I$14) -> 0 | J20: =COUNTIFS('ЕЖЕДНЕВНЫЙ ОТЧЕТ'!$M$5:$M$410,'Отчет по Строительство'!E20,'ЕЖЕДНЕВНЫЙ ОТЧЕТ'!$I$5:$I$410,"",'ЕЖЕДНЕВНЫЙ ОТЧЕТ'!$N$5:$N$410,$J$14) -> 1
D21: 7 | E21: Отдел кадров | H21: =COUNTIFS('ЕЖЕДНЕВНЫЙ ОТЧЕТ'!$M$5:$M$410,'Отчет по Строительство'!E21,'ЕЖЕДНЕВНЫЙ ОТЧЕТ'!$I$5:$I$410,"") -> 3 | I21: =COUNTIFS('ЕЖЕДНЕВНЫЙ ОТЧЕТ'!$M$5:$M$410,'Отчет по Строительство'!E21,'ЕЖЕДНЕВНЫЙ ОТЧЕТ'!$I$5:$I$410,"",'ЕЖЕДНЕВНЫЙ ОТЧЕТ'!$N$5:$N$410,$I$14) -> 2 | J21: =COUNTIFS('ЕЖЕДНЕВНЫЙ ОТЧЕТ'!$M$5:$M$410,'Отчет по Строительство'!E21,'ЕЖЕДНЕВНЫЙ ОТЧЕТ'!$I$5:$I$410,"",'ЕЖЕДНЕВНЫЙ ОТЧЕТ'!$N$5:$N$410,$J$14) -> 1
D22: 8 | E22: Учет персонала | H22: =COUNTIFS('ЕЖЕДНЕВНЫЙ ОТЧЕТ'!$M$5:$M$410,'Отчет по Строительство'!E22,'ЕЖЕДНЕВНЫЙ ОТЧЕТ'!$I$5:$I$410,"") -> 1 | I22: =COUNTIFS('ЕЖЕДНЕВНЫЙ ОТЧЕТ'!$M$5:$M$410,'Отчет по Строительство'!E22,'ЕЖЕДНЕВНЫЙ ОТЧЕТ'!$I$5:$I$410,"",'ЕЖЕДНЕВНЫЙ ОТЧЕТ'!$N$5:$N$410,$I$14) -> 1 | J22: =COUNTIFS('ЕЖЕДНЕВНЫЙ ОТЧЕТ'!$M$5:$M$410,'Отчет по Строительство'!E22,'ЕЖЕДНЕВНЫЙ ОТЧЕТ'!$I$5:$I$410,"",'ЕЖЕДНЕВНЫЙ ОТЧЕТ'!$N$5:$N$410,$J$14) -> 0
D23: 9 | E23: Обслуживающий Персонал | H23: =COUNTIFS('ЕЖЕДНЕВНЫЙ ОТЧЕТ'!$M$5:$M$410,'Отчет по Строительство'!E23,'ЕЖЕДНЕВНЫЙ ОТЧЕТ'!$I$5:$I$410,"") -> 6 | I23: =COUNTIFS('ЕЖЕДНЕВНЫЙ ОТЧЕТ'!$M$5:$M$410,'Отчет по Строительство'!E23,'ЕЖЕДНЕВНЫЙ ОТЧЕТ'!$I$5:$I$410,"",'ЕЖЕДНЕВНЫЙ ОТЧЕТ'!$N$5:$N$410,$I$14) -> 1 | J23: =COUNTIFS('ЕЖЕДНЕВНЫЙ ОТЧЕТ'!$M$5:$M$410,'Отчет по Строительство'!E23,'ЕЖЕДНЕВНЫЙ ОТЧЕТ'!$I$5:$I$410,"",'ЕЖЕДНЕВНЫЙ ОТЧЕТ'!$N$5:$N$410,$J$14) -> 5
D24: 10 | E24: Прораб по электро-механическим работам | H24: =COUNTIFS('ЕЖЕДНЕВНЫЙ ОТЧЕТ'!$M$5:$M$410,'Отчет по Строительство'!E24,'ЕЖЕДНЕВНЫЙ ОТЧЕТ'!$I$5:$I$410,"") -> 5 | I24: =COUNTIFS('ЕЖЕДНЕВНЫЙ ОТЧЕТ'!$M$5:$M$410,'Отчет по Строительство'!E24,'ЕЖЕДНЕВНЫЙ ОТЧЕТ'!$I$5:$I$410,"",'ЕЖЕДНЕВНЫЙ ОТЧЕТ'!$N$5:$N$410,$I$14) -> 1 | J24: =COUNTIFS('ЕЖЕДНЕВНЫЙ ОТЧЕТ'!$M$5:$M$410,'Отчет по Строительство'!E24,'ЕЖЕДНЕВНЫЙ ОТЧЕТ'!$I$5:$I$410,"",'ЕЖЕДНЕВНЫЙ ОТЧЕТ'!$N$5:$N$410,$J$14) -> 4
D25: Итого Электро-Механик ИТР | H25: =SUM(H15:H24) -> 46 | I25: =SUM(I15:I24) -> 20 | J25: =SUM(J15:J24) -> 26
D27: Электро-Механик Рабочей Силы | I27: Э | J27: М
D28: 1 | E28: Работник склада | H28: =COUNTIFS('ЕЖЕДНЕВНЫЙ ОТЧЕТ'!$M$5:$M$410,'Отчет по Строительство'!E28,'ЕЖЕДНЕВНЫЙ ОТЧЕТ'!$I$5:$I$410,"") -> 11 | I28: =COUNTIFS('ЕЖЕДНЕВНЫЙ ОТЧЕТ'!$M$5:$M$410,'Отчет по Строительство'!E28,'ЕЖЕДНЕВНЫЙ ОТЧЕТ'!$I$5:$I$410,"",'ЕЖЕДНЕВНЫЙ ОТЧЕТ'!$N$5:$N$410,$I$14) -> 3 | J28: =COUNTIFS('ЕЖЕДНЕВНЫЙ ОТЧЕТ'!$M$5:$M$410,'Отчет по Строительство'!E28,'ЕЖЕДНЕВНЫЙ ОТЧЕТ'!$I$5:$I$410,"",'ЕЖЕДНЕВНЫЙ ОТЧЕТ'!$N$5:$N$410,$J$14) -> 8
D29: 2 | E29: Бригадир по электро-механическим работам | H29: =COUNTIFS('ЕЖЕДНЕВНЫЙ ОТЧЕТ'!$M$5:$M$410,'Отчет по Строительство'!E29,'ЕЖЕДНЕВНЫЙ ОТЧЕТ'!$I$5:$I$410,"") -> 6 | I29: =COUNTIFS('ЕЖЕДНЕВНЫЙ ОТЧЕТ'!$M$5:$M$410,'Отчет по Строительство'!E29,'ЕЖЕДНЕВНЫЙ ОТЧЕТ'!$I$5:$I$410,"",'ЕЖЕДНЕВНЫЙ ОТЧЕТ'!$N$5:$N$410,$I$14) -> 1 | J29: =COUNTIFS('ЕЖЕДНЕВНЫЙ ОТЧЕТ'!$M$5:$M$410,'Отчет по Строительство'!E29,'ЕЖЕДНЕВНЫЙ ОТЧЕТ'!$I$5:$I$410,"",'ЕЖЕДНЕВНЫЙ ОТЧЕТ'!$N$5:$N$410,$J$14) -> 5
D30: 3 | E30: Бригадир электриков по мобилизации | H30: =COUNTIFS('ЕЖЕДНЕВНЫЙ ОТЧЕТ'!$M$5:$M$410,'Отчет по Строительство'!E30,'ЕЖЕДНЕВНЫЙ ОТЧЕТ'!$I$5:$I$410,"") -> 3 | I30: =COUNTIFS('ЕЖЕДНЕВНЫЙ ОТЧЕТ'!$M$5:$M$410,'Отчет по Строительство'!E30,'ЕЖЕДНЕВНЫЙ ОТЧЕТ'!$I$5:$I$410,"",'ЕЖЕДНЕВНЫЙ ОТЧЕТ'!$N$5:$N$410,$I$14) -> 3 | J30: =COUNTIFS('ЕЖЕДНЕВНЫЙ ОТЧЕТ'!$M$5:$M$410,'Отчет по Строительство'!E30,'ЕЖЕДНЕВНЫЙ ОТЧЕТ'!$I$5:$I$410,"",'ЕЖЕДНЕВНЫЙ ОТЧЕТ'!$N$5:$N$410,$J$14) -> 0
D31: 4 | E31: Электрики по мобилизации | H31: =COUNTIFS('ЕЖЕДНЕВНЫЙ ОТЧЕТ'!$M$5:$M$410,'Отчет по Строительство'!E31,'ЕЖЕДНЕВНЫЙ ОТЧЕТ'!$I$5:$I$410,"") -> 8 | I31: =COUNTIFS('ЕЖЕДНЕВНЫЙ ОТЧЕТ'!$M$5:$M$410,'Отчет по Строительство'!E31,'ЕЖЕДНЕВНЫЙ ОТЧЕТ'!$I$5:$I$410,"",'ЕЖЕДНЕВНЫЙ ОТЧЕТ'!$N$5:$N$410,$I$14) -> 8 | J31: =COUNTIFS('ЕЖЕДНЕВНЫЙ ОТЧЕТ'!$M$5:$M$410,'Отчет по Строительство'!E31,'ЕЖЕДНЕВНЫЙ ОТЧЕТ'!$I$5:$I$410,"",'ЕЖЕДНЕВНЫЙ ОТЧЕТ'!$N$5:$N$410,$J$14) -> 0
D32: 5 | E32: Электромонтажники | H32: =COUNTIFS('ЕЖЕДНЕВНЫЙ ОТЧЕТ'!$M$5:$M$410,'Отчет по Строительство'!E32,'ЕЖЕДНЕВНЫЙ ОТЧЕТ'!$I$5:$I$410,"") -> 13 | I32: =COUNTIFS('ЕЖЕДНЕВНЫЙ ОТЧЕТ'!$M$5:$M$410,'Отчет по Строительство'!E32,'ЕЖЕДНЕВНЫЙ ОТЧЕТ'!$I$5:$I$410,"",'ЕЖЕДНЕВНЫЙ ОТЧЕТ'!$N$5:$N$410,$I$14) -> 13 | J32: =COUNTIFS('ЕЖЕДНЕВНЫЙ ОТЧЕТ'!$M$5:$M$410,'Отчет по Строительство'!E32,'ЕЖЕДНЕВНЫЙ ОТЧЕТ'!$I$5:$I$410,"",'ЕЖЕДНЕВНЫЙ ОТЧЕТ'!$N$5:$N$410,$J$14) -> 0
D33: 6 | E33: Монтажники систем вентиляции | H33: =COUNTIFS('ЕЖЕДНЕВНЫЙ ОТЧЕТ'!$M$5:$M$410,'Отчет по Строительство'!E33,'ЕЖЕДНЕВНЫЙ ОТЧЕТ'!$I$5:$I$410,"") -> 55 | I33: =COUNTIFS('ЕЖЕДНЕВНЫЙ ОТЧЕТ'!$M$5:$M$410,'Отчет по Строительство'!E33,'ЕЖЕДНЕВНЫЙ ОТЧЕТ'!$I$5:$I$410,"",'ЕЖЕДНЕВНЫЙ ОТЧЕТ'!$N$5:$N$410,$I$14) -> 0 | J33: =COUNTIFS('ЕЖЕДНЕВНЫЙ ОТЧЕТ'!$M$5:$M$410,'Отчет по Строительство'!E33,'ЕЖЕДНЕВНЫЙ ОТЧЕТ'!$I$5:$I$410,"",'ЕЖЕДНЕВНЫЙ ОТЧЕТ'!$N$5:$N$410,$J$14) -> 55
D34: 7 | E34: Монтажники сантехнических систем | H34: =COUNTIFS('ЕЖЕДНЕВНЫЙ ОТЧЕТ'!$M$5:$M$410,'Отчет по Строительство'!E34,'ЕЖЕДНЕВНЫЙ ОТЧЕТ'!$I$5:$I$410,"") -> 34 | I34: =COUNTIFS('ЕЖЕДНЕВНЫЙ ОТЧЕТ'!$M$5:$M$410,'Отчет по Строительство'!E34,'ЕЖЕДНЕВНЫЙ ОТЧЕТ'!$I$5:$I$410,"",'ЕЖЕДНЕВНЫЙ ОТЧЕТ'!$N$5:$N$410,$I$14) -> 0 | J34: =COUNTIFS('ЕЖЕДНЕВНЫЙ ОТЧЕТ'!$M$5:$M$410,'Отчет по Строительство'!E34,'ЕЖЕДНЕВНЫЙ ОТЧЕТ'!$I$5:$I$410,"",'ЕЖЕДНЕВНЫЙ ОТЧЕТ'!$N$5:$N$410,$J$14) -> 34
D35: 8 | E35: Монтажники по мобилизации | H35: =COUNTIFS('ЕЖЕДНЕВНЫЙ ОТЧЕТ'!$M$5:$M$410,'Отчет по Строительство'!E35,'ЕЖЕДНЕВНЫЙ ОТЧЕТ'!$I$5:$I$410,"") -> 3 | I35: =COUNTIFS('ЕЖЕДНЕВНЫЙ ОТЧЕТ'!$M$5:$M$410,'Отчет по Строительство'!E35,'ЕЖЕДНЕВНЫЙ ОТЧЕТ'!$I$5:$I$410,"",'ЕЖЕДНЕВНЫЙ ОТЧЕТ'!$N$5:$N$410,$I$14) -> 0 | J35: =COUNTIFS('ЕЖЕДНЕВНЫЙ ОТЧЕТ'!$M$5:$M$410,'Отчет по Строительство'!E35,'ЕЖЕДНЕВНЫЙ ОТЧЕТ'!$I$5:$I$410,"",'ЕЖЕДНЕВНЫЙ ОТЧЕТ'!$N$5:$N$410,$J$14) -> 3
D36: Итого Рабочей Силы | H36: =SUM(H28:H35) -> 133 | I36: =SUM(I28:I35) -> 28 | J36: =SUM(J28:J35) -> 105
D39: Итого : | H39: =H41+H43 -> 179 | I39: =I41+I43 -> 48 | J39: =J41+J43 -> 131
D41: ИТР | H41: =H25 -> 46 | I41: =I25 -> 20 | J41: =J25 -> 26
D43: Рабочей Силы | H43: =H36 -> 133 | I43: =I36 -> 28 | J43: =J36 -> 105

Sheet Дата прием на работу сотруд. 
C2: № | D2: Табельный номер | E2: Ф.И.О | F2: Должность в ОТиЗ | G2: Дата выход на работу | H2: Дата подписания трудового контракта | I2: Дата увольнения
C3: 1 | D3: 103991 | E3: Юнал Мехмет Бурак | F3: Руководитель отдела по Электрике проеката А 27 | G3: 45762 | H3: 45762
C4: 2 | D4: 104006 | E4: Агафонов Сергей Анатольевич | F4: Зам.Руководитель отдела по Электрике проеката А 27 | G4: 45762 | H4: 45762
C5: 3 | D5: 107297 | E5: Челик Саадеттин | F5: Зам.Руководитель отдела по Электрике проеката А 27 | G5: 46013
C6: 4 | D6: 104005 | E6: Усманова Феруза Таировна | F6: Начальник группы ПТО по Электрике А 27 | G6: 45762 | H6: 45762
C7: 5 | D7: 106571 | E7: Норов Алишер Рустамович | F7: Ведущий инженер ПТО по Электрике А 27 | G7: 45938 | H7: 45938
C8: 6 | D8: 106863 | E8: Вопилин Денис Алексеевич | F8: Ведущий инженер ПТО по Электрике А 27 | G8: 45968 | H8: 45986
C9: 7 | D9: 107102 | E9: Комиссарюк Светлана Ивановна | F9: Ведущий инженер ПТО по Электрике А 27 | G9: 45992 | H9: 45992
C10: 8 | D10: 101339 | E10: Йалчынели Бахадыр | F10: Пом. Координатора по Механике | G10: 45971 | H10: 45971
C11: 9 | D11: 104043 | E11: Текин Гюрбюз | F11: Руководитель Технического офиса по Электрие А 27 | G11: 45769 | H11: 45923
C12: 10 | D12: 106629 | E12: Ишджен Хюсейин Тунджер | F12: Руководитель Технического офиса по Электрие А 27 | G12: 45952 | H12: 45952
C13: 11 | D13: 103926 | E13: Джошкун Уфук | F13: Инженер по Электрике А 27 | G13: 45757 | H13: 45810
C14: 12 | D14: 106565 | E14: Сайбитинов Руслан Раисович | F14: Инженер по Электрике А 27 | G14: 45933 | H14: 45936
C15: 13 | D15: 106566 | E15: Зейналов Самир Рамил Оглы | F15: Инженер по Электрике А 27 | G15: 45936 | H15: 45936
C16: 14 | D16: 107298 | E16: Дилек Селахаттин | F16: Инженер по Электрике А 27 | G16: 46013
C17: 15 | D17: 107426 | E17: Пантелеев Денис Владимирович | F17: Инженер по Электрике А 27 | G17: 46037 | H17: 46037
C18: 16 | D18: 106750 | E18: Кристев Иван Иванович | F18: Администратор по Электрике А 27 | G18: 45957 | H18: 45957
C19: 17 | D19: 104008 | E19: Озекес Емре | F19: Руководитель отдела по Меканике проекта А 27 | G19: 45768 | H19: 45768
C20: 18 | D20: 104722 | E20: Рафиев Зиёдулло | F20: Зам.Руководитель отдела по Меканике проекта А 27 | G20: 45820 | H20: 45826
C21: 19 | D21: 106305 | E21: Кармилов Мурат | F21: Инженер по Механике А 27 | G21: 45915 | H21: 45936
C22: 20 | D22: 106459 | E22: Алиев Мустафа Юсупович | F22: Инженер по Механике А 27 | G22: 45926 | H22: 45937
C23: 21 | D23: 106749 | E23: Патапеня Павел Александрович | F23: Инженер по Механике А 27 | G23: 45957 | H23: 45957
C24: 22 | D24: 103984 | E24: Холопов Олег Николаевич | F24: Начальник наружных сетям по механическим работам. | G24: 45762 | H24: 45762
C25: 23 | D25: 107296 | E25: Ниязов Хомид Самадович | F25: ИнженерТехнического офиса А 27 по Механике | G25: 46013 | H25: 46034
C26: 24 | D26: 104401 | E26: Енин Руслан Николаевич | F26: Начальник группы ПТО по Механике А 27 | G26: 45796 | H26: 45796
C27: 25 | D27: 102207 | E27: Кулигина Игнат Геннадиевич | F27: Начальник группы ПТО по Механике А 27 | G27: 45566 | H27: 45566
C28: 26 | D28: 107330 | E28: Мередов Керим | F28: Инженер ПТО по Механике А 27 | G28: 46015 | H28: 46034
... C33: 31 | D33: 106312 | E33: Гюл Сюмер | F33: Инженер Дизайн Офиса А 27 | G33: 45901 | H33: 45954
C34: 32 | D34: 106313 | E34: Мурат Джомерт | F34: Инженер Дизайн Офиса А 27 | G34: 45915
C35: 33 | D35: 104778 | E35: Чобан Эмре | F35: Инженер Дизайн Офиса А 27 | G35: 45821 | H35: 45842
C36: 34 | D36: 103137 | E36: Левина Алина Викторовна | F36: Оператор по Снабжению | G36: 45693 | H36: 45694
C37: 35 | D37: 106540 | E37: Ганина Алина Владимировна | F37: Специалист отдела снабжения | G37: 45931 | H37: 45931
C38: 36 | D38: 106476 | E38: Кравец Ольга Сергеевна | F38: Финансовый аналитик | G38: 45962 | H38: 45962
C39: 37 | D39: 107295 | E39: Дендешер Бурак | F39: Системный Администратор | G39: 46010
C40: 38 | D40: 105960 | E40: Хитай Джейхун | F40: Начальник Административного отдела | G40: 45915 | H40: 45901
C41: 39 | D41: 106067 | E41: Дашевская Екатерина Сергеевна | F41: Специалист по кадрам | G41: 45904 | H41: 45904
C42: 40 | D42: 106499 | E42: Ашуров Жасуржон Суннатилло Угли | F42: Пом.Специалист по ОТ и ТБ | G42: 45929 | H42: 45931
C43: 41 | D43: 105494 | E43: Жамолидинов Муроджон Расулжон Угли | F43: Кладовщик | G43: 45882 | H43: 45882
C44: 42 | D44: 107104 | E44: Джошкун Джан | F44: Начальник склада А27-А24 | G44: 45992 | H44: 45994
C45: 43 | D45: 107103 | E45: Борунова Анжелика Витальевна | F45: Администратор | G45: 45992 | H45: 45992
...
